Workbook

Sheet Hotels
A1: Hotel_ID | B1: Hotel_Name | C1: City | D1: State | E1: Star_Rating | F1: Hotel_Type | G1: Total_Rooms | H1: Opened_Year | I1: Base_ADR_INR
A2: H001 | B2: Golden Sands Goa | C2: Goa | D2: Goa | E2: 4 | F2: Boutique | G2: 89 | H2: 2018 | I2: 5100
A3: H002 | B3: Azure Bay Goa | C3: Goa | D3: Goa | E3: 5 | F3: Luxury | G3: 260 | H3: 2008 | I3: 9600
A4: H003 | B4: Lotus Grand Goa | C4: Goa | D4: Goa | E4: 3 | F4: Budget | G4: 45 | H4: 2001 | I4: 2900
A5: H004 | B5: Jade Pavilion Goa | C5: Goa | D5: Goa | E5: 4 | F5: Business | G5: 150 | H5: 1995 | I5: 5500
A6: H005 | B6: Blue Lagoon Jaipur | C6: Jaipur | D6: Rajasthan | E6: 3 | F6: Budget | G6: 84 | H6: 2000 | I6: 3000
A7: H006 | B7: Cedar Crest Jaipur | C7: Jaipur | D7: Rajasthan | E7: 5 | F7: Heritage | G7: 257 | H7: 1999 | I7: 9100
A8: H007 | B8: Jade Pavilion Jaipur | C8: Jaipur | D8: Rajasthan | E8: 4 | F8: Resort | G8: 164 | H8: 2005 | I8: 5400
A9: H008 | B9: Golden Sands Jaipur | C9: Jaipur | D9: Rajasthan | E9: 4 | F9: Business | G9: 125 | H9: 1998 | I9: 4500
A10: H009 | B10: Emerald Court Udaipur | C10: Udaipur | D10: Rajasthan | E10: 4 | F10: Heritage | G10: 158 | H10: 2004 | I10: 5000
A11: H010 | B11: Saffron Suites Udaipur | C11: Udaipur | D11: Rajasthan | E11: 5 | F11: Luxury | G11: 236 | H11: 2017 | I11: 10700
A12: H011 | B12: Orchid Terrace Udaipur | C12: Udaipur | D12: Rajasthan | E12: 4 | F12: Business | G12: 125 | H12: 2002 | I12: 5000
A13: H012 | B13: Maple Leaf Inn Udaipur | C13: Udaipur | D13: Rajasthan | E13: 3 | F13: Business | G13: 53 | H13: 2022 | I13: 3500
... A49: H048 | B49: Maple Leaf Inn Varanasi | C49: Varanasi | D49: Uttar Pradesh | E49: 4 | F49: Business | G49: 121 | H49: 2018 | I49: 3500

Sheet Hotels_Dashboard
B1: Hotels - Dashboard
B3: Total Hotels | D3: Total Rooms | F3: Cities | H3: Avg Star Rating | J3: Avg Base ADR (INR) | L3: Occupancy | N3: GOP Margin
B4: =COUNTA(Hotels!$A$2:$A$49) -> 48 | D4: =SUM(Hotels!$G$2:$G$49) -> 6720 | F4: =SUMPRODUCT(1/COUNTIF(Hotels!$C$2:$C$49,Hotels!$C$2:$C$49)) -> 12 | H4: =AVERAGE(Hotels!$E$2:$E$49) -> 4 | J4: =AVERAGE(Hotels!$I$2:$I$49) -> 5597.9167 | L4: =SUM(Hotel_Performance!$F$2:$F$1153)/SUM(Hotel_Performance!$E$2:$E$1153) -> 0.68968138 | N4: =SUM(Hotel_Performance!$M$2:$M$1153)/SUM(Hotel_Performance!$K$2:$K$1153) -> 0.38413736
B52: Chart data (live formulas - charts above read from these tables)
B54: Hotels by city | H54: Hotels by type | L54: Hotels by star rating
B55: City | C55: Hotels | D55: Rooms | E55: Avg Base ADR | F55: Occupancy | H55: Type | I55: Hotels | J55: Rooms | L55: Stars | M55: Hotels | N55: Avg Base ADR
B56: Agra | C56: =COUNTIF(Hotels!$C$2:$C$49,$B56) -> 4 | D56: =SUMIF(Hotels!$C$2:$C$49,$B56,Hotels!$G$2:$G$49) -> 595 | E56: =AVERAGEIF(Hotels!$C$2:$C$49,$B56,Hotels!$I$2:$I$49) -> 4225 | F56: =SUMIF(Hotel_Performance!$B$2:$B$1153,$B56,Hotel_Performance!$F$2:$F$1153)/SUMIF(Hotel_Performance!$B$2:$B$1153,$B56,Hotel_Performance!$E$2:$E$1153) -> 0.65624496 | H56: Boutique | I56: =COUNTIF(Hotels!$F$2:$F$49,$H56) -> 15 | J56: =SUMIF(Hotels!$F$2:$F$49,$H56,Hotels!$G$2:$G$49) -> 1984 | L56: 3 | M56: =COUNTIF(Hotels!$E$2:$E$49,$L56) -> 12 | N56: =AVERAGEIF(Hotels!$E$2:$E$49,$L56,Hotels!$I$2:$I$49) -> 3000
B57: Bengaluru | C57: =COUNTIF(Hotels!$C$2:$C$49,$B57) -> 4 | D57: =SUMIF(Hotels!$C$2:$C$49,$B57,Hotels!$G$2:$G$49) -> 534 | E57: =AVERAGEIF(Hotels!$C$2:$C$49,$B57,Hotels!$I$2:$I$49) -> 6900 | F57: =SUMIF(Hotel_Performance!$B$2:$B$1153,$B57,Hotel_Performance!$F$2:$F$1153)/SUMIF(Hotel_Performance!$B$2:$B$1153,$B57,Hotel_Performance!$E$2:$E$1153) -> 0.72422913 | H57: Business | I57: =COUNTIF(Hotels!$F$2:$F$49,$H57) -> 9 | J57: =SUMIF(Hotels!$F$2:$F$49,$H57,Hotels!$G$2:$G$49) -> 1034 | L57: 4 | M57: =COUNTIF(Hotels!$E$2:$E$49,$L57) -> 24 | N57: =AVERAGEIF(Hotels!$E$2:$E$49,$L57,Hotels!$I$2:$I$49) -> 5000
B58: Goa | C58: =COUNTIF(Hotels!$C$2:$C$49,$B58) -> 4 | D58: =SUMIF(Hotels!$C$2:$C$49,$B58,Hotels!$G$2:$G$49) -> 544 | E58: =AVERAGEIF(Hotels!$C$2:$C$49,$B58,Hotels!$I$2:$I$49) -> 5775 | F58: =SUMIF(Hotel_Performance!$B$2:$B$1153,$B58,Hotel_Performance!$F$2:$F$1153)/SUMIF(Hotel_Performance!$B$2:$B$1153,$B58,Hotel_Performance!$E$2:$E$1153) -> 0.68841156 | H58: Resort | I58: =COUNTIF(Hotels!$F$2:$F$49,$H58) -> 8 | J58: =SUMIF(Hotels!$F$2:$F$49,$H58,Hotels!$G$2:$G$49) -> 1111 | L58: 5 | M58: =COUNTIF(Hotels!$E$2:$E$49,$L58) -> 12 | N58: =AVERAGEIF(Hotels!$E$2:$E$49,$L58,Hotels!$I$2:$I$49) -> 9391.6667
B59: Jaipur | C59: =COUNTIF(Hotels!$C$2:$C$49,$B59) -> 4 | D59: =SUMIF(Hotels!$C$2:$C$49,$B59,Hotels!$G$2:$G$49) -> 630 | E59: =AVERAGEIF(Hotels!$C$2:$C$49,$B59,Hotels!$I$2:$I$49) -> 5500 | F59: =SUMIF(Hotel_Performance!$B$2:$B$1153,$B59,Hotel_Performance!$F$2:$F$1153)/SUMIF(Hotel_Performance!$B$2:$B$1153,$B59,Hotel_Performance!$E$2:$E$1153) -> 0.69938465 | H59: Luxury | I59: =COUNTIF(Hotels!$F$2:$F$49,$H59) -> 7 | J59: =SUMIF(Hotels!$F$2:$F$49,$H59,Hotels!$G$2:$G$49) -> 1589
B60: Kochi | C60: =COUNTIF(Hotels!$C$2:$C$49,$B60) -> 4 | D60: =SUMIF(Hotels!$C$2:$C$49,$B60,Hotels!$G$2:$G$49) -> 649 | E60: =AVERAGEIF(Hotels!$C$2:$C$49,$B60,Hotels!$I$2:$I$49) -> 5250 | F60: =SUMIF(Hotel_Performance!$B$2:$B$1153,$B60,Hotel_Performance!$F$2:$F$1153)/SUMIF(Hotel_Performance!$B$2:$B$1153,$B60,Hotel_Performance!$E$2:$E$1153) -> 0.70765139 | H60: Budget | I60: =COUNTIF(Hotels!$F$2:$F$49,$H60) -> 5 | J60: =SUMIF(Hotels!$F$2:$F$49,$H60,Hotels!$G$2:$G$49) -> 355
B61: Manali | C61: =COUNTIF(Hotels!$C$2:$C$49,$B61) -> 4 | D61: =SUMIF(Hotels!$C$2:$C$49,$B61,Hotels!$G$2:$G$49) -> 454 | E61: =AVERAGEIF(Hotels!$C$2:$C$49,$B61,Hotels!$I$2:$I$49) -> 4950 | F61: =SUMIF(Hotel_Performance!$B$2:$B$1153,$B61,Hotel_Performance!$F$2:$F$1153)/SUMIF(Hotel_Performance!$B$2:$B$1153,$B61,Hotel_Performance!$E$2:$E$1153) -> 0.68507634 | H61: Heritage | I61: =COUNTIF(Hotels!$F$2:$F$49,$H61) -> 4 | J61: =SUMIF(Hotels!$F$2:$F$49,$H61,Hotels!$G$2:$G$49) -> 647
B62: Mumbai | C62: =COUNTIF(Hotels!$C$2:$C$49,$B62) -> 4 | D62: =SUMIF(Hotels!$C$2:$C$49,$B62,Hotels!$G$2:$G$49) -> 503 | E62: =AVERAGEIF(Hotels!$C$2:$C$49,$B62,Hotels!$I$2:$I$49) -> 8050 | F62: =SUMIF(Hotel_Performance!$B$2:$B$1153,$B62,Hotel_Performance!$F$2:$F$1153)/SUMIF(Hotel_Performance!$B$2:$B$1153,$B62,Hotel_Performance!$E$2:$E$1153) -> 0.65009123
B63: New Delhi | C63: =COUNTIF(Hotels!$C$2:$C$49,$B63) -> 4 | D63: =SUMIF(Hotels!$C$2:$C$49,$B63,Hotels!$G$2:$G$49) -> 658 | E63: =AVERAGEIF(Hotels!$C$2:$C$49,$B63,Hotels!$I$2:$I$49) -> 7375 | F63: =SUMIF(Hotel_Performance!$B$2:$B$1153,$B63,Hotel_Performance!$F$2:$F$1153)/SUMIF(Hotel_Performance!$B$2:$B$1153,$B63,Hotel_Performance!$E$2:$E$1153) -> 0.718006
B64: Rishikesh | C64: =COUNTIF(Hotels!$C$2:$C$49,$B64) -> 4 | D64: =SUMIF(Hotels!$C$2:$C$49,$B64,Hotels!$G$2:$G$49) -> 598 | E64: =AVERAGEIF(Hotels!$C$2:$C$49,$B64,Hotels!$I$2:$I$49) -> 4125 | F64: =SUMIF(Hotel_Performance!$B$2:$B$1153,$B64,Hotel_Performance!$F$2:$F$1153)/SUMIF(Hotel_Performance!$B$2:$B$1153,$B64,Hotel_Performance!$E$2:$E$1153) -> 0.68807898
B65: Shimla | C65: =COUNTIF(Hotels!$C$2:$C$49,$B65) -> 4 | D65: =SUMIF(Hotels!$C$2:$C$49,$B65,Hotels!$G$2:$G$49) -> 554 | E65: =AVERAGEIF(Hotels!$C$2:$C$49,$B65,Hotels!$I$2:$I$49) -> 4775 | F65: =SUMIF(Hotel_Performance!$B$2:$B$1153,$B65,Hotel_Performance!$F$2:$F$1153)/SUMIF(Hotel_Performance!$B$2:$B$1153,$B65,Hotel_Performance!$E$2:$E$1153) -> 0.68081203
B66: Udaipur | C66: =COUNTIF(Hotels!$C$2:$C$49,$B66) -> 4 | D66: =SUMIF(Hotels!$C$2:$C$49,$B66,Hotels!$G$2:$G$49) -> 572 | E66: =AVERAGEIF(Hotels!$C$2:$C$49,$B66,Hotels!$I$2:$I$49) -> 6050 | F66: =SUMIF(Hotel_Performance!$B$2:$B$1153,$B66,Hotel_Performance!$F$2:$F$1153)/SUMIF(Hotel_Performance!$B$2:$B$1153,$B66,Hotel_Performance!$E$2:$E$1153) -> 0.69259508
B67: Varanasi | C67: =COUNTIF(Hotels!$C$2:$C$49,$B67) -> 4 | D67: =SUMIF(Hotels!$C$2:$C$49,$B67,Hotels!$G$2:$G$49) -> 429 | E67: =AVERAGEIF(Hotels!$C$2:$C$49,$B67,Hotels!$I$2:$I$49) -> 4200 | F67: =SUMIF(Hotel_Performance!$B$2:$B$1153,$B67,Hotel_Performance!$F$2:$F$1153)/SUMIF(Hotel_Performance!$B$2:$B$1153,$B67,Hotel_Performance!$E$2:$E$1153) -> 0.67087844

Sheet Customers
A1: Customer_ID | B1: Full_Name | C1: Gender | D1: Age | E1: Age_Group | F1: Country | G1: Home_City | H1: Customer_Type | I1: Segment | J1: Loyalty_Tier | K1: Signup_Date | L1: Acquisition_Source | M1: Email_Opt_In | N1: Total_Bookings | O1: Completed_Stays | P1: Lifetime_Revenue_INR | Q1: Customer_Status
A2: C0001 | B2: Shreya Kulkarni | C2: Female | D2: 35 | E2: =IF(D2<25,"18-24",IF(D2<35,"25-34",IF(D2<45,"35-44",IF(D2<55,"45-54","55+")))) -> 35-44 | F2: India | G2: Kolkata | H2: Domestic | I2: Leisure | J2: None | K2: 45711 | L2: Organic Search | M2: Yes | N2: =COUNTIF(Bookings!$B$2:$B$5001,A2) -> 2 | O2: =COUNTIFS(Bookings!$B$2:$B$5001,A2,Bookings!$Q$2:$Q$5001,"Completed") -> 1 | P2: =SUMIFS(Revenue!$L$2:$L$4092,Revenue!$B$2:$B$4092,A2) -> 22280 | Q2: =IF(N2=0,"Inactive",IF(N2=1,"One-time",IF(N2<4,"Repeat","Loyal"))) -> Repeat
A3: C0002 | B3: Rahul Iyer | C3: Male | D3: 38 | E3: =IF(D3<25,"18-24",IF(D3<35,"25-34",IF(D3<45,"35-44",IF(D3<55,"45-54","55+")))) -> 35-44 | F3: India | G3: Hyderabad | H3: Domestic | I3: Business | J3: None | K3: 45786 | L3: Travel Partner | M3: Yes | N3: =COUNTIF(Bookings!$B$2:$B$5001,A3) -> 2 | O3: =COUNTIFS(Bookings!$B$2:$B$5001,A3,Bookings!$Q$2:$Q$5001,"Completed") -> 2 | P3: =SUMIFS(Revenue!$L$2:$L$4092,Revenue!$B$2:$B$4092,A3) -> 35260 | Q3: =IF(N3=0,"Inactive",IF(N3=1,"One-time",IF(N3<4,"Repeat","Loyal"))) -> Repeat
A4: C0003 | B4: Rohan Bose | C4: Male | D4: 38 | E4: =IF(D4<25,"18-24",IF(D4<35,"25-34",IF(D4<45,"35-44",IF(D4<55,"45-54","55+")))) -> 35-44 | F4: India | G4: Ahmedabad | H4: Domestic | I4: Leisure | J4: None | K4: 45158 | L4: Social Media | M4: Yes | N4: =COUNTIF(Bookings!$B$2:$B$5001,A4) -> 0 | O4: =COUNTIFS(Bookings!$B$2:$B$5001,A4,Bookings!$Q$2:$Q$5001,"Completed") -> 0 | P4: =SUMIFS(Revenue!$L$2:$L$4092,Revenue!$B$2:$B$4092,A4) -> 0 | Q4: =IF(N4=0,"Inactive",IF(N4=1,"One-time",IF(N4<4,"Repeat","Loyal"))) -> Inactive
A5: C0004 | B5: Rajesh Nair | C5: Male | D5: 39 | E5: =IF(D5<25,"18-24",IF(D5<35,"25-34",IF(D5<45,"35-44",IF(D5<55,"45-54","55+")))) -> 35-44 | F5: India | G5: Chennai | H5: Domestic | I5: Leisure | J5: None | K5: 45699 | L5: Organic Search | M5: Yes | N5: =COUNTIF(Bookings!$B$2:$B$5001,A5) -> 2 | O5: =COUNTIFS(Bookings!$B$2:$B$5001,A5,Bookings!$Q$2:$Q$5001,"Completed") -> 2 | P5: =SUMIFS(Revenue!$L$2:$L$4092,Revenue!$B$2:$B$4092,A5) -> 95110 | Q5: =IF(N5=0,"Inactive",IF(N5=1,"One-time",IF(N5<4,"Repeat","Loyal"))) -> Repeat
A6: C0005 | B6: Shreya Kulkarni | C6: Male | D6: 18 | E6: =IF(D6<25,"18-24",IF(D6<35,"25-34",IF(D6<45,"35-44",IF(D6<55,"45-54","55+")))) -> 18-24 | F6: India | G6: Ahmedabad | H6: Domestic | I6: Couple | J6: None | K6: 45841 | L6: Travel Partner | M6: No | N6: =COUNTIF(Bookings!$B$2:$B$5001,A6) -> 2 | O6: =COUNTIFS(Bookings!$B$2:$B$5001,A6,Bookings!$Q$2:$Q$5001,"Completed") -> 1 | P6: =SUMIFS(Revenue!$L$2:$L$4092,Revenue!$B$2:$B$4092,A6) -> 28110 | Q6: =IF(N6=0,"Inactive",IF(N6=1,"One-time",IF(N6<4,"Repeat","Loyal"))) -> Repeat
A7: C0006 | B7: Vivaan Rao | C7: Female | D7: 37 | E7: =IF(D7<25,"18-24",IF(D7<35,"25-34",IF(D7<45,"35-44",IF(D7<55,"45-54","55+")))) -> 35-44 | F7: India | G7: Delhi | H7: Domestic | I7: Business | J7: None | K7: 45742 | L7: Travel Partner | M7: No | N7: =COUNTIF(Bookings!$B$2:$B$5001,A7) -> 2 | O7: =COUNTIFS(Bookings!$B$2:$B$5001,A7,Bookings!$Q$2:$Q$5001,"Completed") -> 2 | P7: =SUMIFS(Revenue!$L$2:$L$4092,Revenue!$B$2:$B$4092,A7) -> 95910 | Q7: =IF(N7=0,"Inactive",IF(N7=1,"One-time",IF(N7<4,"Repeat","Loyal"))) -> Repeat
A8: C0007 | B8: Aarav Singh | C8: Female | D8: 31 | E8: =IF(D8<25,"18-24",IF(D8<35,"25-34",IF(D8<45,"35-44",IF(D8<55,"45-54","55+")))) -> 25-34 | F8: India | G8: Bhopal | H8: Domestic | I8: Family | J8: None | K8: 45523 | L8: Social Media | M8: Yes | N8: =COUNTIF(Bookings!$B$2:$B$5001,A8) -> 2 | O8: =COUNTIFS(Bookings!$B$2:$B$5001,A8,Bookings!$Q$2:$Q$5001,"Completed") -> 2 | P8: =SUMIFS(Revenue!$L$2:$L$4092,Revenue!$B$2:$B$4092,A8) -> 85350 | Q8: =IF(N8=0,"Inactive",IF(N8=1,"One-time",IF(N8<4,"Repeat","Loyal"))) -> Repeat
A9: C0008 | B9: Deepak Khan | C9: Male | D9: 36 | E9: =IF(D9<25,"18-24",IF(D9<35,"25-34",IF(D9<45,"35-44",IF(D9<55,"45-54","55+")))) -> 35-44 | F9: India | G9: Bengaluru | H9: Domestic | I9: Leisure | J9: None | K9: 45547 | L9: Email Campaign | M9: No | N9: =COUNTIF(Bookings!$B$2:$B$5001,A9) -> 3 | O9: =COUNTIFS(Bookings!$B$2:$B$5001,A9,Bookings!$Q$2:$Q$5001,"Completed") -> 2 | P9: =SUMIFS(Revenue!$L$2:$L$4092,Revenue!$B$2:$B$4092,A9) -> 35710 | Q9: =IF(N9=0,"Inactive",IF(N9=1,"One-time",IF(N9<4,"Repeat","Loyal"))) -> Repeat
A10: C0009 | B10: Nisha Chopra | C10: Female | D10: 43 | E10: =IF(D10<25,"18-24",IF(D10<35,"25-34",IF(D10<45,"35-44",IF(D10<55,"45-54","55+")))) -> 35-44 | F10: India | G10: Hyderabad | H10: Domestic | I10: Business | J10: None | K10: 45912 | L10: Organic Search | M10: Yes | N10: =COUNTIF(Bookings!$B$2:$B$5001,A10) -> 1 | O10: =COUNTIFS(Bookings!$B$2:$B$5001,A10,Bookings!$Q$2:$Q$5001,"Completed") -> 1 | P10: =SUMIFS(Revenue!$L$2:$L$4092,Revenue!$B$2:$B$4092,A10) -> 37170 | Q10: =IF(N10=0,"Inactive",IF(N10=1,"One-time",IF(N10<4,"Repeat","Loyal"))) -> One-time
A11: C0010 | B11: Manish Sharma | C11: Male | D11: 35 | E11: =IF(D11<25,"18-24",IF(D11<35,"25-34",IF(D11<45,"35-44",IF(D11<55,"45-54","55+")))) -> 35-44 | F11: India | G11: Bengaluru | H11: Domestic | I11: Leisure | J11: None | K11: 45994 | L11: Email Campaign | M11: Yes | N11: =COUNTIF(Bookings!$B$2:$B$5001,A11) -> 2 | O11: =COUNTIFS(Bookings!$B$2:$B$5001,A11,Bookings!$Q$2:$Q$5001,"Completed") -> 1 | P11: =SUMIFS(Revenue!$L$2:$L$4092,Revenue!$B$2:$B$4092,A11) -> 89550 | Q11: =IF(N11=0,"Inactive",IF(N11=1,"One-time",IF(N11<4,"Repeat","Loyal"))) -> Repeat
A12: C0011 | B12: Hugo Clarke | C12: Male | D12: 23 | E12: =IF(D12<25,"18-24",IF(D12<35,"25-34",IF(D12<45,"35-44",IF(D12<55,"45-54","55+")))) -> 18-24 | F12: UAE | G12: Dubai | H12: International | I12: Leisure | J12: Gold | K12: 45380 | L12: Email Campaign | M12: No | N12: =COUNTIF(Bookings!$B$2:$B$5001,A12) -> 7 | O12: =COUNTIFS(Bookings!$B$2:$B$5001,A12,Bookings!$Q$2:$Q$5001,"Completed") -> 7 | P12: =SUMIFS(Revenue!$L$2:$L$4092,Revenue!$B$2:$B$4092,A12) -> 275570 | Q12: =IF(N12=0,"Inactive",IF(N12=1,"One-time",IF(N12<4,"Repeat","Loyal"))) -> Loyal
A13: C0012 | B13: Meera Tiwari | C13: Male | D13: 36 | E13: =IF(D13<25,"18-24",IF(D13<35,"25-34",IF(D13<45,"35-44",IF(D13<55,"45-54","55+")))) -> 35-44 | F13: India | G13: Surat | H13: Domestic | I13: Couple | J13: None | K13: 45932 | L13: Travel Partner | M13: No | N13: =COUNTIF(Bookings!$B$2:$B$5001,A13) -> 3 | O13: =COUNTIFS(Bookings!$B$2:$B$5001,A13,Bookings!$Q$2:$Q$5001,"Completed") -> 3 | P13: =SUMIFS(Revenue!$L$2:$L$4092,Revenue!$B$2:$B$4092,A13) -> 127930 | Q13: =IF(N13=0,"Inactive",IF(N13=1,"One-time",IF(N13<4,"Repeat","Loyal"))) -> Repeat
... A1501: C1500 | B1501: Sneha Shah | C1501: Male | D1501: 63 | E1501: =IF(D1501<25,"18-24",IF(D1501<35,"25-34",IF(D1501<45,"35-44",IF(D1501<55,"45-54","55+")))) -> 55+ | F1501: India | G1501: Chandigarh | H1501: Domestic | I1501: Leisure | J1501: Silver | K1501: 45543 | L1501: Referral | M1501: Yes | N1501: =COUNTIF(Bookings!$B$2:$B$5001,A1501) -> 3 | O1501: =COUNTIFS(Bookings!$B$2:$B$5001,A1501,Bookings!$Q$2:$Q$5001,"Completed") -> 1 | P1501: =SUMIFS(Revenue!$L$2:$L$4092,Revenue!$B$2:$B$4092,A1501) -> 40840 | Q1501: =IF(N1501=0,"Inactive",IF(N1501=1,"One-time",IF(N1501<4,"Repeat","Loyal"))) -> Repeat

Sheet Customers_Dashboard
B1: Customers - Dashboard
B3: Total Customers | D3: Active (1+ booking) | F3: Repeat Rate | H3: Lifetime Revenue (Cr) | J3: Avg CLV (INR) | L3: International Share | N3: Loyalty Members
B4: =COUNTA(Customers!$A$2:$A$1501) -> 1500 | D4: =COUNTIF(Customers!$N$2:$N$1501,">=1") -> 1122 | F4: =COUNTIF(Customers!$N$2:$N$1501,">=2")/COUNTIF(Customers!$N$2:$N$1501,">=1") -> 0.79055258 | H4: =SUM(Customers!$P$2:$P$1501)/10000000 -> 20.838432 | J4: =SUM(Customers!$P$2:$P$1501)/COUNTIF(Customers!$N$2:$N$1501,">=1") -> 185725.78 | L4: =COUNTIF(Customers!$H$2:$H$1501,"International")/COUNTA(Customers!$A$2:$A$1501) -> 0.22 | N4: =1-COUNTIF(Customers!$J$2:$J$1501,"None")/COUNTA(Customers!$A$2:$A$1501) -> 0.34266667
B52: Chart data (live formulas - charts above read from these tables)
B54: By segment | H54: By loyalty tier | L54: By age group
B55: Segment | C55: Customers | D55: Active | E55: Lifetime Rev (Lakh) | F55: Avg CLV | H55: Tier | I55: Customers | J55: Lifetime Rev (Lakh) | L55: Age | M55: Customers
B56: Leisure | C56: =COUNTIF(Customers!$I$2:$I$1501,$B56) -> 548 | D56: =COUNTIFS(Customers!$I$2:$I$1501,$B56,Customers!$N$2:$N$1501,">=1") -> 405 | E56: =SUMIF(Customers!$I$2:$I$1501,$B56,Customers!$P$2:$P$1501)/100000 -> 563.9898 | F56: =SUMIF(Customers!$I$2:$I$1501,$B56,Customers!$P$2:$P$1501)/COUNTIFS(Customers!$I$2:$I$1501,$B56,Customers!$N$2:$N$1501,">=1") -> 139256.74 | H56: None | I56: =COUNTIF(Customers!$J$2:$J$1501,$H56) -> 986 | J56: =SUMIF(Customers!$J$2:$J$1501,$H56,Customers!$P$2:$P$1501)/100000 -> 483.0047 | L56: 18-24 | M56: =COUNTIF(Customers!$E$2:$E$1501,$L56) -> 201
B57: Family | C57: =COUNTIF(Customers!$I$2:$I$1501,$B57) -> 328 | D57: =COUNTIFS(Customers!$I$2:$I$1501,$B57,Customers!$N$2:$N$1501,">=1") -> 242 | E57: =SUMIF(Customers!$I$2:$I$1501,$B57,Customers!$P$2:$P$1501)/100000 -> 560.1033 | F57: =SUMIF(Customers!$I$2:$I$1501,$B57,Customers!$P$2:$P$1501)/COUNTIFS(Customers!$I$2:$I$1501,$B57,Customers!$N$2:$N$1501,">=1") -> 231447.64 | H57: Silver | I57: =COUNTIF(Customers!$J$2:$J$1501,$H57) -> 221 | J57: =SUMIF(Customers!$J$2:$J$1501,$H57,Customers!$P$2:$P$1501)/100000 -> 362.7514 | L57: 25-34 | M57: =COUNTIF(Customers!$E$2:$E$1501,$L57) -> 481
B58: Business | C58: =COUNTIF(Customers!$I$2:$I$1501,$B58) -> 258 | D58: =COUNTIFS(Customers!$I$2:$I$1501,$B58,Customers!$N$2:$N$1501,">=1") -> 204 | E58: =SUMIF(Customers!$I$2:$I$1501,$B58,Customers!$P$2:$P$1501)/100000 -> 284.6405 | F58: =SUMIF(Customers!$I$2:$I$1501,$B58,Customers!$P$2:$P$1501)/COUNTIFS(Customers!$I$2:$I$1501,$B58,Customers!$N$2:$N$1501,">=1") -> 139529.66 | H58: Gold | I58: =COUNTIF(Customers!$J$2:$J$1501,$H58) -> 145 | J58: =SUMIF(Customers!$J$2:$J$1501,$H58,Customers!$P$2:$P$1501)/100000 -> 395.5721 | L58: 35-44 | M58: =COUNTIF(Customers!$E$2:$E$1501,$L58) -> 544
B59: Couple | C59: =COUNTIF(Customers!$I$2:$I$1501,$B59) -> 257 | D59: =COUNTIFS(Customers!$I$2:$I$1501,$B59,Customers!$N$2:$N$1501,">=1") -> 190 | E59: =SUMIF(Customers!$I$2:$I$1501,$B59,Customers!$P$2:$P$1501)/100000 -> 258.361 | F59: =SUMIF(Customers!$I$2:$I$1501,$B59,Customers!$P$2:$P$1501)/COUNTIFS(Customers!$I$2:$I$1501,$B59,Customers!$N$2:$N$1501,">=1") -> 135979.47 | H59: Platinum | I59: =COUNTIF(Customers!$J$2:$J$1501,$H59) -> 148 | J59: =SUMIF(Customers!$J$2:$J$1501,$H59,Customers!$P$2:$P$1501)/100000 -> 842.515 | L59: 45-54 | M59: =COUNTIF(Customers!$E$2:$E$1501,$L59) -> 234
B60: Group | C60: =COUNTIF(Customers!$I$2:$I$1501,$B60) -> 109 | D60: =COUNTIFS(Customers!$I$2:$I$1501,$B60,Customers!$N$2:$N$1501,">=1") -> 81 | E60: =SUMIF(Customers!$I$2:$I$1501,$B60,Customers!$P$2:$P$1501)/100000 -> 416.7486 | F60: =SUMIF(Customers!$I$2:$I$1501,$B60,Customers!$P$2:$P$1501)/COUNTIFS(Customers!$I$2:$I$1501,$B60,Customers!$N$2:$N$1501,">=1") -> 514504.44 | L60: 55+ | M60: =COUNTIF(Customers!$E$2:$E$1501,$L60) -> 40
B63: By acquisition source | E63: By customer type
B64: Source | C64: Customers | E64: Type | F64: Customers
B65: Corporate Tie-up | C65: =COUNTIF(Customers!$L$2:$L$1501,$B65) -> 127 | E65: Domestic | F65: =COUNTIF(Customers!$H$2:$H$1501,$E65) -> 1170
B66: Organic Search | C66: =COUNTIF(Customers!$L$2:$L$1501,$B66) -> 257 | E66: International | F66: =COUNTIF(Customers!$H$2:$H$1501,$E66) -> 330
B67: Referral | C67: =COUNTIF(Customers!$L$2:$L$1501,$B67) -> 271
B68: Email Campaign | C68: =COUNTIF(Customers!$L$2:$L$1501,$B68) -> 273
B69: Social Media | C69: =COUNTIF(Customers!$L$2:$L$1501,$B69) -> 282
B70: Travel Partner | C70: =COUNTIF(Customers!$L$2:$L$1501,$B70) -> 290

Sheet Bookings
A1: Booking_ID | B1: Customer_ID | C1: Hotel_ID | D1: Hotel_City | E1: Booking_Date | F1: Check_In | G1: Check_Out | H1: Check_In_Month | I1: Nights | J1: Lead_Time_Days | K1: Room_Type | L1: Rooms_Booked | M1: Adults | N1: Children | O1: Channel | P1: Payment_Method | Q1: Booking_Status | R1: Room_Rate_INR | S1: Booking_Value_INR | T1: Total_Guests
A2: BK00001 | B2: C1269 | C2: H020 | D2: =INDEX(Hotels!$C$2:$C$49,MATCH(C2,Hotels!$A$2:$A$49,0)) -> Mumbai | E2: 45302 | F2: 45572 | G2: 45575 | H2: =DATE(YEAR(F2),MONTH(F2),1) -> 45566 | I2: =G2-F2 -> 3 | J2: =F2-E2 -> 270 | K2: Suite | L2: 2 | M2: 4 | N2: 2 | O2: Mobile App | P2: Digital Wallet | Q2: Completed | R2: 26500 | S2: =I2*L2*R2 -> 159000 | T2: =M2+N2 -> 6
A3: BK00002 | B3: C0630 | C3: H002 | D3: =INDEX(Hotels!$C$2:$C$49,MATCH(C3,Hotels!$A$2:$A$49,0)) -> Goa | E3: 45323 | F3: 45584 | G3: 45587 | H3: =DATE(YEAR(F3),MONTH(F3),1) -> 45566 | I3: =G3-F3 -> 3 | J3: =F3-E3 -> 261 | K3: Suite | L3: 1 | M3: 2 | N3: 3 | O3: OTA - Agoda | P3: UPI | Q3: Cancelled | R3: 19400 | S3: =I3*L3*R3 -> 58200 | T3: =M3+N3 -> 5
A4: BK00003 | B4: C0747 | C4: H014 | D4: =INDEX(Hotels!$C$2:$C$49,MATCH(C4,Hotels!$A$2:$A$49,0)) -> Agra | E4: 45332 | F4: 45602 | G4: 45605 | H4: =DATE(YEAR(F4),MONTH(F4),1) -> 45597 | I4: =G4-F4 -> 3 | J4: =F4-E4 -> 270 | K4: Deluxe | L4: 1 | M4: 1 | N4: 0 | O4: OTA - Agoda | P4: Credit Card | Q4: Completed | R4: 6200 | S4: =I4*L4*R4 -> 18600 | T4: =M4+N4 -> 1
A5: BK00004 | B5: C0547 | C5: H004 | D5: =INDEX(Hotels!$C$2:$C$49,MATCH(C5,Hotels!$A$2:$A$49,0)) -> Goa | E5: 45362 | F5: 45632 | G5: 45636 | H5: =DATE(YEAR(F5),MONTH(F5),1) -> 45627 | I5: =G5-F5 -> 4 | J5: =F5-E5 -> 270 | K5: Suite | L5: 2 | M5: 4 | N5: 0 | O5: Travel Agent | P5: Cash | Q5: Completed | R5: 13900 | S5: =I5*L5*R5 -> 111200 | T5: =M5+N5 -> 4
A6: BK00005 | B6: C0702 | C6: H020 | D6: =INDEX(Hotels!$C$2:$C$49,MATCH(C6,Hotels!$A$2:$A$49,0)) -> Mumbai | E6: 45364 | F6: 45568 | G6: 45572 | H6: =DATE(YEAR(F6),MONTH(F6),1) -> 45566 | I6: =G6-F6 -> 4 | J6: =F6-E6 -> 204 | K6: Deluxe | L6: 1 | M6: 2 | N6: 2 | O6: Walk-in | P6: Debit Card | Q6: Completed | R6: 18050 | S6: =I6*L6*R6 -> 72200 | T6: =M6+N6 -> 4
A7: BK00006 | B7: C1184 | C7: H038 | D7: =INDEX(Hotels!$C$2:$C$49,MATCH(C7,Hotels!$A$2:$A$49,0)) -> Manali | E7: 45369 | F7: 45639 | G7: 45643 | H7: =DATE(YEAR(F7),MONTH(F7),1) -> 45627 | I7: =G7-F7 -> 4 | J7: =F7-E7 -> 270 | K7: Suite | L7: 1 | M7: 2 | N7: 2 | O7: Mobile App | P7: Credit Card | Q7: No-Show | R7: 11100 | S7: =I7*L7*R7 -> 44400 | T7: =M7+N7 -> 4
A8: BK00007 | B8: C1337 | C8: H021 | D8: =INDEX(Hotels!$C$2:$C$49,MATCH(C8,Hotels!$A$2:$A$49,0)) -> New Delhi | E8: 45369 | F8: 45605 | G8: 45609 | H8: =DATE(YEAR(F8),MONTH(F8),1) -> 45597 | I8: =G8-F8 -> 4 | J8: =F8-E8 -> 236 | K8: Premium Suite | L8: 4 | M8: 8 | N8: 0 | O8: Travel Agent | P8: UPI | Q8: Completed | R8: 25050 | S8: =I8*L8*R8 -> 400800 | T8: =M8+N8 -> 8
A9: BK00008 | B9: C0100 | C9: H030 | D9: =INDEX(Hotels!$C$2:$C$49,MATCH(C9,Hotels!$A$2:$A$49,0)) -> Kochi | E9: 45376 | F9: 45585 | G9: 45587 | H9: =DATE(YEAR(F9),MONTH(F9),1) -> 45566 | I9: =G9-F9 -> 2 | J9: =F9-E9 -> 209 | K9: Standard | L9: 2 | M9: 4 | N9: 0 | O9: Travel Agent | P9: UPI | Q9: Completed | R9: 5500 | S9: =I9*L9*R9 -> 22000 | T9: =M9+N9 -> 4
A10: BK00009 | B10: C0062 | C10: H016 | D10: =INDEX(Hotels!$C$2:$C$49,MATCH(C10,Hotels!$A$2:$A$49,0)) -> Agra | E10: 45378 | F10: 45648 | G10: 45653 | H10: =DATE(YEAR(F10),MONTH(F10),1) -> 45627 | I10: =G10-F10 -> 5 | J10: =F10-E10 -> 270 | K10: Standard | L10: 1 | M10: 3 | N10: 0 | O10: Direct Website | P10: Credit Card | Q10: Completed | R10: 8950 | S10: =I10*L10*R10 -> 44750 | T10: =M10+N10 -> 3
A11: BK00010 | B11: C0100 | C11: H010 | D11: =INDEX(Hotels!$C$2:$C$49,MATCH(C11,Hotels!$A$2:$A$49,0)) -> Udaipur | E11: 45385 | F11: 45655 | G11: 45659 | H11: =DATE(YEAR(F11),MONTH(F11),1) -> 45627 | I11: =G11-F11 -> 4 | J11: =F11-E11 -> 270 | K11: Deluxe | L11: 3 | M11: 6 | N11: 0 | O11: OTA - Agoda | P11: Net Banking | Q11: Cancelled | R11: 18250 | S11: =I11*L11*R11 -> 219000 | T11: =M11+N11 -> 6
A12: BK00011 | B12: C1323 | C12: H005 | D12: =INDEX(Hotels!$C$2:$C$49,MATCH(C12,Hotels!$A$2:$A$49,0)) -> Jaipur | E12: 45387 | F12: 45579 | G12: 45583 | H12: =DATE(YEAR(F12),MONTH(F12),1) -> 45566 | I12: =G12-F12 -> 4 | J12: =F12-E12 -> 192 | K12: Deluxe | L12: 1 | M12: 2 | N12: 0 | O12: Mobile App | P12: Credit Card | Q12: Completed | R12: 5100 | S12: =I12*L12*R12 -> 20400 | T12: =M12+N12 -> 2
A13: BK00012 | B13: C0682 | C13: H022 | D13: =INDEX(Hotels!$C$2:$C$49,MATCH(C13,Hotels!$A$2:$A$49,0)) -> New Delhi | E13: 45390 | F13: 45660 | G13: 45664 | H13: =DATE(YEAR(F13),MONTH(F13),1) -> 45658 | I13: =G13-F13 -> 4 | J13: =F13-E13 -> 270 | K13: Standard | L13: 1 | M13: 1 | N13: 0 | O13: OTA - Agoda | P13: Debit Card | Q13: Cancelled | R13: 5250 | S13: =I13*L13*R13 -> 21000 | T13: =M13+N13 -> 1
... A5001: BK05000 | B5001: C1223 | C5001: H006 | D5001: =INDEX(Hotels!$C$2:$C$49,MATCH(C5001,Hotels!$A$2:$A$49,0)) -> Jaipur | E5001: 46293 | F5001: 46295 | G5001: 46297 | H5001: =DATE(YEAR(F5001),MONTH(F5001),1) -> 46266 | I5001: =G5001-F5001 -> 2 | J5001: =F5001-E5001 -> 2 | K5001: Deluxe | L5001: 1 | M5001: 1 | N5001: 0 | O5001: OTA - Agoda | P5001: Credit Card | Q5001: Completed | R5001: 10000 | S5001: =I5001*L5001*R5001 -> 20000 | T5001: =M5001+N5001 -> 1

Sheet Bookings_Dashboard
B1: Bookings - Dashboard
B3: Total Bookings | D3: Cancellation Rate | F3: No-show Rate | H3: Avg Lead Time (days) | J3: Avg Stay (nights) | L3: Avg Booking Value | N3: Avg Guests
B4: =COUNTA(Bookings!$A$2:$A$5001) -> 5000 | D4: =COUNTIF(Bookings!$Q$2:$Q$5001,"Cancelled")/COUNTA(Bookings!$A$2:$A$5001) -> 0.1544 | F4: =COUNTIF(Bookings!$Q$2:$Q$5001,"No-Show")/COUNTA(Bookings!$A$2:$A$5001) -> 0.0274 | H4: =AVERAGE(Bookings!$J$2:$J$5001) -> 41.0406 | J4: =AVERAGEIF(Bookings!$Q$2:$Q$5001,"Completed",Bookings!$I$2:$I$5001) -> 3.1532633 | L4: =AVERAGEIF(Bookings!$Q$2:$Q$5001,"Completed",Bookings!$S$2:$S$5001) -> 43144.195 | N4: =AVERAGE(Bookings!$T$2:$T$5001) -> 2.6092
B67: Chart data (live formulas - charts above read from these tables)
B69: By status | E69: By channel | K69: By room type
B70: Status | C70: Bookings | E70: Channel | F70: Bookings | G70: Cancel Rate | H70: Avg Lead (d) | I70: Avg Value | K70: Room | L70: Bookings | M70: Avg Value
B71: Completed | C71: =COUNTIF(Bookings!$Q$2:$Q$5001,$B71) -> 4091 | E71: Walk-in | F71: =COUNTIF(Bookings!$O$2:$O$5001,$E71) -> 130 | G71: =COUNTIFS(Bookings!$O$2:$O$5001,$E71,Bookings!$Q$2:$Q$5001,"Cancelled")/COUNTIF(Bookings!$O$2:$O$5001,$E71) -> 0.038461538 | H71: =AVERAGEIF(Bookings!$O$2:$O$5001,$E71,Bookings!$J$2:$J$5001) -> 44.138462 | I71: =AVERAGEIFS(Bookings!$S$2:$S$5001,Bookings!$O$2:$O$5001,$E71,Bookings!$Q$2:$Q$5001,"Completed") -> 40091.6 | K71: Standard | L71: =COUNTIF(Bookings!$K$2:$K$5001,$K71) -> 1581 | M71: =AVERAGEIFS(Bookings!$S$2:$S$5001,Bookings!$K$2:$K$5001,$K71,Bookings!$Q$2:$Q$5001,"Completed") -> 26103.711
B72: Cancelled | C72: =COUNTIF(Bookings!$Q$2:$Q$5001,$B72) -> 772 | E72: OTA - Agoda | F72: =COUNTIF(Bookings!$O$2:$O$5001,$E72) -> 361 | G72: =COUNTIFS(Bookings!$O$2:$O$5001,$E72,Bookings!$Q$2:$Q$5001,"Cancelled")/COUNTIF(Bookings!$O$2:$O$5001,$E72) -> 0.2299169 | H72: =AVERAGEIF(Bookings!$O$2:$O$5001,$E72,Bookings!$J$2:$J$5001) -> 46.67867 | I72: =AVERAGEIFS(Bookings!$S$2:$S$5001,Bookings!$O$2:$O$5001,$E72,Bookings!$Q$2:$Q$5001,"Completed") -> 48889.739 | K72: Deluxe | L72: =COUNTIF(Bookings!$K$2:$K$5001,$K72) -> 1859 | M72: =AVERAGEIFS(Bookings!$S$2:$S$5001,Bookings!$K$2:$K$5001,$K72,Bookings!$Q$2:$Q$5001,"Completed") -> 36364.673
B73: No-Show | C73: =COUNTIF(Bookings!$Q$2:$Q$5001,$B73) -> 137 | E73: Travel Agent | F73: =COUNTIF(Bookings!$O$2:$O$5001,$E73) -> 654 | G73: =COUNTIFS(Bookings!$O$2:$O$5001,$E73,Bookings!$Q$2:$Q$5001,"Cancelled")/COUNTIF(Bookings!$O$2:$O$5001,$E73) -> 0.1559633 | H73: =AVERAGEIF(Bookings!$O$2:$O$5001,$E73,Bookings!$J$2:$J$5001) -> 61.111621 | I73: =AVERAGEIFS(Bookings!$S$2:$S$5001,Bookings!$O$2:$O$5001,$E73,Bookings!$Q$2:$Q$5001,"Completed") -> 68903.289 | K73: Suite | L73: =COUNTIF(Bookings!$K$2:$K$5001,$K73) -> 1108 | M73: =AVERAGEIFS(Bookings!$S$2:$S$5001,Bookings!$K$2:$K$5001,$K73,Bookings!$Q$2:$Q$5001,"Completed") -> 58694.239
E74: Corporate Booking | F74: =COUNTIF(Bookings!$O$2:$O$5001,$E74) -> 664 | G74: =COUNTIFS(Bookings!$O$2:$O$5001,$E74,Bookings!$Q$2:$Q$5001,"Cancelled")/COUNTIF(Bookings!$O$2:$O$5001,$E74) -> 0.063253012 | H74: =AVERAGEIF(Bookings!$O$2:$O$5001,$E74,Bookings!$J$2:$J$5001) -> 12.537651 | I74: =AVERAGEIFS(Bookings!$S$2:$S$5001,Bookings!$O$2:$O$5001,$E74,Bookings!$Q$2:$Q$5001,"Completed") -> 24626.578 | K74: Premium Suite | L74: =COUNTIF(Bookings!$K$2:$K$5001,$K74) -> 452 | M74: =AVERAGEIFS(Bookings!$S$2:$S$5001,Bookings!$K$2:$K$5001,$K74,Bookings!$Q$2:$Q$5001,"Completed") -> 92554.244
E75: Mobile App | F75: =COUNTIF(Bookings!$O$2:$O$5001,$E75) -> 696 | G75: =COUNTIFS(Bookings!$O$2:$O$5001,$E75,Bookings!$Q$2:$Q$5001,"Cancelled")/COUNTIF(Bookings!$O$2:$O$5001,$E75) -> 0.11063218 | H75: =AVERAGEIF(Bookings!$O$2:$O$5001,$E75,Bookings!$J$2:$J$5001) -> 39.593391 | I75: =AVERAGEIFS(Bookings!$S$2:$S$5001,Bookings!$O$2:$O$5001,$E75,Bookings!$Q$2:$Q$5001,"Completed") -> 40032.862
E76: OTA - Booking.com | F76: =COUNTIF(Bookings!$O$2:$O$5001,$E76) -> 702 | G76: =COUNTIFS(Bookings!$O$2:$O$5001,$E76,Bookings!$Q$2:$Q$5001,"Cancelled")/COUNTIF(Bookings!$O$2:$O$5001,$E76) -> 0.26210826 | H76: =AVERAGEIF(Bookings!$O$2:$O$5001,$E76,Bookings!$J$2:$J$5001) -> 41.578348 | I76: =AVERAGEIFS(Bookings!$S$2:$S$5001,Bookings!$O$2:$O$5001,$E76,Bookings!$Q$2:$Q$5001,"Completed") -> 41444.311
E77: OTA - MakeMyTrip | F77: =COUNTIF(Bookings!$O$2:$O$5001,$E77) -> 896 | G77: =COUNTIFS(Bookings!$O$2:$O$5001,$E77,Bookings!$Q$2:$Q$5001,"Cancelled")/COUNTIF(Bookings!$O$2:$O$5001,$E77) -> 0.21763393 | H77: =AVERAGEIF(Bookings!$O$2:$O$5001,$E77,Bookings!$J$2:$J$5001) -> 44.733259 | I77: =AVERAGEIFS(Bookings!$S$2:$S$5001,Bookings!$O$2:$O$5001,$E77,Bookings!$Q$2:$Q$5001,"Completed") -> 44009.925
E78: Direct Website | F78: =COUNTIF(Bookings!$O$2:$O$5001,$E78) -> 897 | G78: =COUNTIFS(Bookings!$O$2:$O$5001,$E78,Bookings!$Q$2:$Q$5001,"Cancelled")/COUNTIF(Bookings!$O$2:$O$5001,$E78) -> 0.093645485 | H78: =AVERAGEIF(Bookings!$O$2:$O$5001,$E78,Bookings!$J$2:$J$5001) -> 41.801561 | I78: =AVERAGEIFS(Bookings!$S$2:$S$5001,Bookings!$O$2:$O$5001,$E78,Bookings!$Q$2:$Q$5001,"Completed") -> 41158.144
B81: By payment method | E81: By city | I81: By check-in month
B82: Payment | C82: Bookings | E82: City | F82: Bookings | G82: Cancel Rate | I82: Month | J82: Bookings | K82: Cancelled | L82: Completed Value (Lakh) | M82: Key
B83: UPI | C83: =COUNTIF(Bookings!$P$2:$P$5001,$B83) -> 1694 | E83: Kochi | F83: =COUNTIF(Bookings!$D$2:$D$5001,$E83) -> 515 | G83: =COUNTIFS(Bookings!$D$2:$D$5001,$E83,Bookings!$Q$2:$Q$5001,"Cancelled")/COUNTIF(Bookings!$D$2:$D$5001,$E83) -> 0.16699029 | I83: =TEXT($M83,"mmm yy") -> Oct 24 | J83: =COUNTIF(Bookings!$H$2:$H$5001,$M83) -> 212 | K83: =COUNTIFS(Bookings!$H$2:$H$5001,$M83,Bookings!$Q$2:$Q$5001,"Cancelled") -> 29 | L83: =SUMIFS(Bookings!$S$2:$S$5001,Bookings!$H$2:$H$5001,$M83,Bookings!$Q$2:$Q$5001,"Completed")/100000 -> 78.3475 | M83: 45566
B84: Credit Card | C84: =COUNTIF(Bookings!$P$2:$P$5001,$B84) -> 1383 | E84: New Delhi | F84: =COUNTIF(Bookings!$D$2:$D$5001,$E84) -> 474 | G84: =COUNTIFS(Bookings!$D$2:$D$5001,$E84,Bookings!$Q$2:$Q$5001,"Cancelled")/COUNTIF(Bookings!$D$2:$D$5001,$E84) -> 0.15611814 | I84: =TEXT($M84,"mmm yy") -> Nov 24 | J84: =COUNTIF(Bookings!$H$2:$H$5001,$M84) -> 217 | K84: =COUNTIFS(Bookings!$H$2:$H$5001,$M84,Bookings!$Q$2:$Q$5001,"Cancelled") -> 40 | L84: =SUMIFS(Bookings!$S$2:$S$5001,Bookings!$H$2:$H$5001,$M84,Bookings!$Q$2:$Q$5001,"Completed")/100000 -> 82.0815 | M84: 45597
B85: Debit Card | C85: =COUNTIF(Bookings!$P$2:$P$5001,$B85) -> 734 | E85: Agra | F85: =COUNTIF(Bookings!$D$2:$D$5001,$E85) -> 461 | G85: =COUNTIFS(Bookings!$D$2:$D$5001,$E85,Bookings!$Q$2:$Q$5001,"Cancelled")/COUNTIF(Bookings!$D$2:$D$5001,$E85) -> 0.17570499 | I85: =TEXT($M85,"mmm yy") -> Dec 24 | J85: =COUNTIF(Bookings!$H$2:$H$5001,$M85) -> 239 | K85: =COUNTIFS(Bookings!$H$2:$H$5001,$M85,Bookings!$Q$2:$Q$5001,"Cancelled") -> 41 | L85: =SUMIFS(Bookings!$S$2:$S$5001,Bookings!$H$2:$H$5001,$M85,Bookings!$Q$2:$Q$5001,"Completed")/100000 -> 91.4995 | M85: 45627
B86: Net Banking | C86: =COUNTIF(Bookings!$P$2:$P$5001,$B86) -> 494 | E86: Rishikesh | F86: =COUNTIF(Bookings!$D$2:$D$5001,$E86) -> 458 | G86: =COUNTIFS(Bookings!$D$2:$D$5001,$E86,Bookings!$Q$2:$Q$5001,"Cancelled")/COUNTIF(Bookings!$D$2:$D$5001,$E86) -> 0.1790393 | I86: =TEXT($M86,"mmm yy") -> Jan 25 | J86: =COUNTIF(Bookings!$H$2:$H$5001,$M86) -> 233 | K86: =COUNTIFS(Bookings!$H$2:$H$5001,$M86,Bookings!$Q$2:$Q$5001,"Cancelled") -> 34 | L86: =SUMIFS(Bookings!$S$2:$S$5001,Bookings!$H$2:$H$5001,$M86,Bookings!$Q$2:$Q$5001,"Completed")/100000 -> 105.4095 | M86: 45658
B87: Digital Wallet | C87: =COUNTIF(Bookings!$P$2:$P$5001,$B87) -> 401 | E87: Jaipur | F87: =COUNTIF(Bookings!$D$2:$D$5001,$E87) -> 454 | G87: =COUNTIFS(Bookings!$D$2:$D$5001,$E87,Bookings!$Q$2:$Q$5001,"Cancelled")/COUNTIF(Bookings!$D$2:$D$5001,$E87) -> 0.14537445 | I87: =TEXT($M87,"mmm yy") -> Feb 25 | J87: =COUNTIF(Bookings!$H$2:$H$5001,$M87) -> 288 | K87: =COUNTIFS(Bookings!$H$2:$H$5001,$M87,Bookings!$Q$2:$Q$5001,"Cancelled") -> 41 | L87: =SUMIFS(Bookings!$S$2:$S$5001,Bookings!$H$2:$H$5001,$M87,Bookings!$Q$2:$Q$5001,"Completed")/100000 -> 111.7295 | M87: 45689
B88: Cash | C88: =COUNTIF(Bookings!$P$2:$P$5001,$B88) -> 294 | E88: Goa | F88: =COUNTIF(Bookings!$D$2:$D$5001,$E88) -> 422 | G88: =COUNTIFS(Bookings!$D$2:$D$5001,$E88,Bookings!$Q$2:$Q$5001,"Cancelled")/COUNTIF(Bookings!$D$2:$D$5001,$E88) -> 0.16824645 | I88: =TEXT($M88,"mmm yy") -> Mar 25 | J88: =COUNTIF(Bookings!$H$2:$H$5001,$M88) -> 197 | K88: =COUNTIFS(Bookings!$H$2:$H$5001,$M88,Bookings!$Q$2:$Q$5001,"Cancelled") -> 28 | L88: =SUMIFS(Bookings!$S$2:$S$5001,Bookings!$H$2:$H$5001,$M88,Bookings!$Q$2:$Q$5001,"Completed")/100000 -> 63.721 | M88: 45717
E89: Shimla | F89: =COUNTIF(Bookings!$D$2:$D$5001,$E89) -> 402 | G89: =COUNTIFS(Bookings!$D$2:$D$5001,$E89,Bookings!$Q$2:$Q$5001,"Cancelled")/COUNTIF(Bookings!$D$2:$D$5001,$E89) -> 0.16169154 | I89: =TEXT($M89,"mmm yy") -> Apr 25 | J89: =COUNTIF(Bookings!$H$2:$H$5001,$M89) -> 175 | K89: =COUNTIFS(Bookings!$H$2:$H$5001,$M89,Bookings!$Q$2:$Q$5001,"Cancelled") -> 34 | L89: =SUMIFS(Bookings!$S$2:$S$5001,Bookings!$H$2:$H$5001,$M89,Bookings!$Q$2:$Q$5001,"Completed")/100000 -> 51.89 | M89: 45748
E90: Udaipur | F90: =COUNTIF(Bookings!$D$2:$D$5001,$E90) -> 399 | G90: =COUNTIFS(Bookings!$D$2:$D$5001,$E90,Bookings!$Q$2:$Q$5001,"Cancelled")/COUNTIF(Bookings!$D$2:$D$5001,$E90) -> 0.15789474 | I90: =TEXT($M90,"mmm yy") -> May 25 | J90: =COUNTIF(Bookings!$H$2:$H$5001,$M90) -> 189 | K90: =COUNTIFS(Bookings!$H$2:$H$5001,$M90,Bookings!$Q$2:$Q$5001,"Cancelled") -> 21 | L90: =SUMIFS(Bookings!$S$2:$S$5001,Bookings!$H$2:$H$5001,$M90,Bookings!$Q$2:$Q$5001,"Completed")/100000 -> 73.869 | M90: 45778
E91: Bengaluru | F91: =COUNTIF(Bookings!$D$2:$D$5001,$E91) -> 372 | G91: =COUNTIFS(Bookings!$D$2:$D$5001,$E91,Bookings!$Q$2:$Q$5001,"Cancelled")/COUNTIF(Bookings!$D$2:$D$5001,$E91) -> 0.11827957 | I91: =TEXT($M91,"mmm yy") -> Jun 25 | J91: =COUNTIF(Bookings!$H$2:$H$5001,$M91) -> 143 | K91: =COUNTIFS(Bookings!$H$2:$H$5001,$M91,Bookings!$Q$2:$Q$5001,"Cancelled") -> 13 | L91: =SUMIFS(Bookings!$S$2:$S$5001,Bookings!$H$2:$H$5001,$M91,Bookings!$Q$2:$Q$5001,"Completed")/100000 -> 38.826 | M91: 45809
E92: Manali | F92: =COUNTIF(Bookings!$D$2:$D$5001,$E92) -> 357 | G92: =COUNTIFS(Bookings!$D$2:$D$5001,$E92,Bookings!$Q$2:$Q$5001,"Cancelled")/COUNTIF(Bookings!$D$2:$D$5001,$E92) -> 0.10644258 | I92: =TEXT($M92,"mmm yy") -> Jul 25 | J92: =COUNTIF(Bookings!$H$2:$H$5001,$M92) -> 129 | K92: =COUNTIFS(Bookings!$H$2:$H$5001,$M92,Bookings!$Q$2:$Q$5001,"Cancelled") -> 18 | L92: =SUMIFS(Bookings!$S$2:$S$5001,Bookings!$H$2:$H$5001,$M92,Bookings!$Q$2:$Q$5001,"Completed")/100000 -> 42.963 | M92: 45839
E93: Varanasi | F93: =COUNTIF(Bookings!$D$2:$D$5001,$E93) -> 346 | G93: =COUNTIFS(Bookings!$D$2:$D$5001,$E93,Bookings!$Q$2:$Q$5001,"Cancelled")/COUNTIF(Bookings!$D$2:$D$5001,$E93) -> 0.13583815 | I93: =TEXT($M93,"mmm yy") -> Aug 25 | J93: =COUNTIF(Bookings!$H$2:$H$5001,$M93) -> 109 | K93: =COUNTIFS(Bookings!$H$2:$H$5001,$M93,Bookings!$Q$2:$Q$5001,"Cancelled") -> 19 | L93: =SUMIFS(Bookings!$S$2:$S$5001,Bookings!$H$2:$H$5001,$M93,Bookings!$Q$2:$Q$5001,"Completed")/100000 -> 26.5385 | M93: 45870
E94: Mumbai | F94: =COUNTIF(Bookings!$D$2:$D$5001,$E94) -> 340 | G94: =COUNTIFS(Bookings!$D$2:$D$5001,$E94,Bookings!$Q$2:$Q$5001,"Cancelled")/COUNTIF(Bookings!$D$2:$D$5001,$E94) -> 0.16176471 | I94: =TEXT($M94,"mmm yy") -> Sep 25 | J94: =COUNTIF(Bookings!$H$2:$H$5001,$M94) -> 146 | K94: =COUNTIFS(Bookings!$H$2:$H$5001,$M94,Bookings!$Q$2:$Q$5001,"Cancelled") -> 14 | L94: =SUMIFS(Bookings!$S$2:$S$5001,Bookings!$H$2:$H$5001,$M94,Bookings!$Q$2:$Q$5001,"Completed")/100000 -> 43.8735 | M94: 45901
I95: =TEXT($M95,"mmm yy") -> Oct 25 | J95: =COUNTIF(Bookings!$H$2:$H$5001,$M95) -> 259 | K95: =COUNTIFS(Bookings!$H$2:$H$5001,$M95,Bookings!$Q$2:$Q$5001,"Cancelled") -> 41 | L95: =SUMIFS(Bookings!$S$2:$S$5001,Bookings!$H$2:$H$5001,$M95,Bookings!$Q$2:$Q$5001,"Completed")/100000 -> 98.477 | M95: 45931
I96: =TEXT($M96,"mmm yy") -> Nov 25 | J96: =COUNTIF(Bookings!$H$2:$H$5001,$M96) -> 254 | K96: =COUNTIFS(Bookings!$H$2:$H$5001,$M96,Bookings!$Q$2:$Q$5001,"Cancelled") -> 41 | L96: =SUMIFS(Bookings!$S$2:$S$5001,Bookings!$H$2:$H$5001,$M96,Bookings!$Q$2:$Q$5001,"Completed")/100000 -> 100.507 | M96: 45962
I97: =TEXT($M97,"mmm yy") -> Dec 25 | J97: =COUNTIF(Bookings!$H$2:$H$5001,$M97) -> 321 | K97: =COUNTIFS(Bookings!$H$2:$H$5001,$M97,Bookings!$Q$2:$Q$5001,"Cancelled") -> 43 | L97: =SUMIFS(Bookings!$S$2:$S$5001,Bookings!$H$2:$H$5001,$M97,Bookings!$Q$2:$Q$5001,"Completed")/100000 -> 119.175 | M97: 45992
I98: =TEXT($M98,"mmm yy") -> Jan 26 | J98: =COUNTIF(Bookings!$H$2:$H$5001,$M98) -> 318 | K98: =COUNTIFS(Bookings!$H$2:$H$5001,$M98,Bookings!$Q$2:$Q$5001,"Cancelled") -> 53 | L98: =SUMIFS(Bookings!$S$2:$S$5001,Bookings!$H$2:$H$5001,$M98,Bookings!$Q$2:$Q$5001,"Completed")/100000 -> 119.4145 | M98: 46023
I99: =TEXT($M99,"mmm yy") -> Feb 26 | J99: =COUNTIF(Bookings!$H$2:$H$5001,$M99) -> 265 | K99: =COUNTIFS(Bookings!$H$2:$H$5001,$M99,Bookings!$Q$2:$Q$5001,"Cancelled") -> 39 | L99: =SUMIFS(Bookings!$S$2:$S$5001,Bookings!$H$2:$H$5001,$M99,Bookings!$Q$2:$Q$5001,"Completed")/100000 -> 108.7645 | M99: 46054
I100: =TEXT($M100,"mmm yy") -> Mar 26 | J100: =COUNTIF(Bookings!$H$2:$H$5001,$M100) -> 264 | K100: =COUNTIFS(Bookings!$H$2:$H$5001,$M100,Bookings!$Q$2:$Q$5001,"Cancelled") -> 53 | L100: =SUMIFS(Bookings!$S$2:$S$5001,Bookings!$H$2:$H$5001,$M100,Bookings!$Q$2:$Q$5001,"Completed")/100000 -> 95.0455 | M100: 46082
I101: =TEXT($M101,"mmm yy") -> Apr 26 | J101: =COUNTIF(Bookings!$H$2:$H$5001,$M101) -> 229 | K101: =COUNTIFS(Bookings!$H$2:$H$5001,$M101,Bookings!$Q$2:$Q$5001,"Cancelled") -> 48 | L101: =SUMIFS(Bookings!$S$2:$S$5001,Bookings!$H$2:$H$5001,$M101,Bookings!$Q$2:$Q$5001,"Completed")/100000 -> 70.164 | M101: 46113
I102: =TEXT($M102,"mmm yy") -> May 26 | J102: =COUNTIF(Bookings!$H$2:$H$5001,$M102) -> 239 | K102: =COUNTIFS(Bookings!$H$2:$H$5001,$M102,Bookings!$Q$2:$Q$5001,"Cancelled") -> 36 | L102: =SUMIFS(Bookings!$S$2:$S$5001,Bookings!$H$2:$H$5001,$M102,Bookings!$Q$2:$Q$5001,"Completed")/100000 -> 81.3385 | M102: 46143
I103: =TEXT($M103,"mmm yy") -> Jun 26 | J103: =COUNTIF(Bookings!$H$2:$H$5001,$M103) -> 166 | K103: =COUNTIFS(Bookings!$H$2:$H$5001,$M103,Bookings!$Q$2:$Q$5001,"Cancelled") -> 27 | L103: =SUMIFS(Bookings!$S$2:$S$5001,Bookings!$H$2:$H$5001,$M103,Bookings!$Q$2:$Q$5001,"Completed")/100000 -> 48.646 | M103: 46174
I104: =TEXT($M104,"mmm yy") -> Jul 26 | J104: =COUNTIF(Bookings!$H$2:$H$5001,$M104) -> 126 | K104: =COUNTIFS(Bookings!$H$2:$H$5001,$M104,Bookings!$Q$2:$Q$5001,"Cancelled") -> 14 | L104: =SUMIFS(Bookings!$S$2:$S$5001,Bookings!$H$2:$H$5001,$M104,Bookings!$Q$2:$Q$5001,"Completed")/100000 -> 28.5675 | M104: 46204
I105: =TEXT($M105,"mmm yy") -> Aug 26 | J105: =COUNTIF(Bookings!$H$2:$H$5001,$M105) -> 134 | K105: =COUNTIFS(Bookings!$H$2:$H$5001,$M105,Bookings!$Q$2:$Q$5001,"Cancelled") -> 23 | L105: =SUMIFS(Bookings!$S$2:$S$5001,Bookings!$H$2:$H$5001,$M105,Bookings!$Q$2:$Q$5001,"Completed")/100000 -> 41.27 | M105: 46235
I106: =TEXT($M106,"mmm yy") -> Sep 26 | J106: =COUNTIF(Bookings!$H$2:$H$5001,$M106) -> 148 | K106: =COUNTIFS(Bookings!$H$2:$H$5001,$M106,Bookings!$Q$2:$Q$5001,"Cancelled") -> 22 | L106: =SUMIFS(Bookings!$S$2:$S$5001,Bookings!$H$2:$H$5001,$M106,Bookings!$Q$2:$Q$5001,"Completed")/100000 -> 42.911 | M106: 46266

Sheet Revenue
A1: Booking_ID | B1: Customer_ID | C1: Hotel_ID | D1: City | E1: Stay_Month | F1: Channel | G1: Room_Nights | H1: Room_Revenue_INR | I1: FnB_Revenue_INR | J1: Spa_Revenue_INR | K1: Other_Revenue_INR | L1: Total_Revenue_INR | M1: Commission_Pct | N1: Commission_INR | O1: Net_Revenue_INR
A2: BK00001 | B2: C1269 | C2: H020 | D2: Mumbai | E2: 45566 | F2: Mobile App | G2: 6 | H2: 159000 | I2: 15590 | J2: 0 | K2: 0 | L2: =SUM(H2:K2) -> 174590 | M2: 0 | N2: =H2*M2 -> 0 | O2: =L2-N2 -> 174590
A3: BK00003 | B3: C0747 | C3: H014 | D3: Agra | E3: 45597 | F3: OTA - Agoda | G3: 3 | H3: 18600 | I3: 1070 | J3: 0 | K3: 0 | L3: =SUM(H3:K3) -> 19670 | M3: 0.16 | N3: =H3*M3 -> 2976 | O3: =L3-N3 -> 16694
A4: BK00004 | B4: C0547 | C4: H004 | D4: Goa | E4: 45627 | F4: Travel Agent | G4: 8 | H4: 111200 | I4: 9270 | J4: 5030 | K4: 0 | L4: =SUM(H4:K4) -> 125500 | M4: 0.1 | N4: =H4*M4 -> 11120 | O4: =L4-N4 -> 114380
A5: BK00005 | B5: C0702 | C5: H020 | D5: Mumbai | E5: 45566 | F5: Walk-in | G5: 4 | H5: 72200 | I5: 20160 | J5: 0 | K5: 2130 | L5: =SUM(H5:K5) -> 94490 | M5: 0 | N5: =H5*M5 -> 0 | O5: =L5-N5 -> 94490
A6: BK00007 | B6: C1337 | C6: H021 | D6: New Delhi | E6: 45597 | F6: Travel Agent | G6: 16 | H6: 400800 | I6: 11250 | J6: 0 | K6: 0 | L6: =SUM(H6:K6) -> 412050 | M6: 0.1 | N6: =H6*M6 -> 40080 | O6: =L6-N6 -> 371970
A7: BK00008 | B7: C0100 | C7: H030 | D7: Kochi | E7: 45566 | F7: Travel Agent | G7: 4 | H7: 22000 | I7: 5910 | J7: 6550 | K7: 0 | L7: =SUM(H7:K7) -> 34460 | M7: 0.1 | N7: =H7*M7 -> 2200 | O7: =L7-N7 -> 32260
A8: BK00009 | B8: C0062 | C8: H016 | D8: Agra | E8: 45627 | F8: Direct Website | G8: 5 | H8: 44750 | I8: 5760 | J8: 0 | K8: 0 | L8: =SUM(H8:K8) -> 50510 | M8: 0 | N8: =H8*M8 -> 0 | O8: =L8-N8 -> 50510
A9: BK00011 | B9: C1323 | C9: H005 | D9: Jaipur | E9: 45566 | F9: Mobile App | G9: 4 | H9: 20400 | I9: 4870 | J9: 0 | K9: 0 | L9: =SUM(H9:K9) -> 25270 | M9: 0 | N9: =H9*M9 -> 0 | O9: =L9-N9 -> 25270
A10: BK00014 | B10: C1002 | C10: H006 | D10: Jaipur | E10: 45658 | F10: Travel Agent | G10: 6 | H10: 190800 | I10: 2270 | J10: 0 | K10: 1650 | L10: =SUM(H10:K10) -> 194720 | M10: 0.1 | N10: =H10*M10 -> 19080 | O10: =L10-N10 -> 175640
A11: BK00015 | B11: C0011 | C11: H013 | D11: Agra | E11: 45658 | F11: Mobile App | G11: 2 | H11: 18400 | I11: 1960 | J11: 0 | K11: 0 | L11: =SUM(H11:K11) -> 20360 | M11: 0 | N11: =H11*M11 -> 0 | O11: =L11-N11 -> 20360
A12: BK00016 | B12: C0462 | C12: H009 | D12: Udaipur | E12: 45566 | F12: Travel Agent | G12: 12 | H12: 94800 | I12: 6460 | J12: 0 | K12: 2200 | L12: =SUM(H12:K12) -> 103460 | M12: 0.1 | N12: =H12*M12 -> 9480 | O12: =L12-N12 -> 93980
A13: BK00018 | B13: C1346 | C13: H043 | D13: Rishikesh | E13: 45627 | F13: Travel Agent | G13: 4 | H13: 27200 | I13: 8660 | J13: 6180 | K13: 1470 | L13: =SUM(H13:K13) -> 43510 | M13: 0.1 | N13: =H13*M13 -> 2720 | O13: =L13-N13 -> 40790
... A4092: BK05000 | B4092: C1223 | C4092: H006 | D4092: Jaipur | E4092: 46266 | F4092: OTA - Agoda | G4092: 2 | H4092: 20000 | I4092: 1770 | J4092: 0 | K4092: 0 | L4092: =SUM(H4092:K4092) -> 21770 | M4092: 0.16 | N4092: =H4092*M4092 -> 3200 | O4092: =L4092-N4092 -> 18570

Sheet Revenue_Dashboard
B1: Revenue - Dashboard
B3: Gross Revenue (Cr) | D3: Net Revenue (Cr) | F3: Commission (Cr) | H3: Ancillary Share | J3: Avg Revenue / Stay | L3: Room Nights | N3: Commission % of Gross
B4: =SUM(Revenue!$L$2:$L$4092)/10000000 -> 20.838432 | D4: =SUM(Revenue!$O$2:$O$4092)/10000000 -> 19.39282 | F4: =SUM(Revenue!$N$2:$N$4092)/10000000 -> 1.4456117 | H4: =1-SUM(Revenue!$H$2:$H$4092)/SUM(Revenue!$L$2:$L$4092) -> 0.15299337 | J4: =AVERAGE(Revenue!$L$2:$L$4092) -> 50937.257 | L4: =SUM(Revenue!$G$2:$G$4092) -> 15866 | N4: =SUM(Revenue!$N$2:$N$4092)/SUM(Revenue!$L$2:$L$4092) -> 0.069372381
B52: Chart data (live formulas - charts above read from these tables)
B54: By stay month | I54: Revenue mix | L54: By city
B55: Month | C55: Gross (Lakh) | D55: Net (Lakh) | E55: Commission (Lakh) | F55: Room Nights | G55: Key | I55: Stream | J55: Revenue (Cr) | L55: City | M55: Gross (Cr) | N55: Stays | O55: Avg / Stay
B56: =TEXT($G56,"mmm yy") -> Oct 24 | C56: =SUMIF(Revenue!$E$2:$E$4092,$G56,Revenue!$L$2:$L$4092)/100000 -> 92.0966 | D56: =SUMIF(Revenue!$E$2:$E$4092,$G56,Revenue!$O$2:$O$4092)/100000 -> 85.31832 | E56: =SUMIF(Revenue!$E$2:$E$4092,$G56,Revenue!$N$2:$N$4092)/100000 -> 6.77828 | F56: =SUMIF(Revenue!$E$2:$E$4092,$G56,Revenue!$G$2:$G$4092) -> 680 | G56: 45566 | I56: Room | J56: =SUM(Revenue!$H$2:$H$4092)/10000000 -> 17.65029 | L56: Varanasi | M56: =SUMIF(Revenue!$D$2:$D$4092,$L56,Revenue!$L$2:$L$4092)/10000000 -> 1.097568 | N56: =COUNTIF(Revenue!$D$2:$D$4092,$L56) -> 292 | O56: =SUMIF(Revenue!$D$2:$D$4092,$L56,Revenue!$L$2:$L$4092)/COUNTIF(Revenue!$D$2:$D$4092,$L56) -> 37587.945
B57: =TEXT($G57,"mmm yy") -> Nov 24 | C57: =SUMIF(Revenue!$E$2:$E$4092,$G57,Revenue!$L$2:$L$4092)/100000 -> 95.5519 | D57: =SUMIF(Revenue!$E$2:$E$4092,$G57,Revenue!$O$2:$O$4092)/100000 -> 89.41324 | E57: =SUMIF(Revenue!$E$2:$E$4092,$G57,Revenue!$N$2:$N$4092)/100000 -> 6.13866 | F57: =SUMIF(Revenue!$E$2:$E$4092,$G57,Revenue!$G$2:$G$4092) -> 659 | G57: 45597 | I57: F&B | J57: =SUM(Revenue!$I$2:$I$4092)/10000000 -> 2.266839 | L57: Shimla | M57: =SUMIF(Revenue!$D$2:$D$4092,$L57,Revenue!$L$2:$L$4092)/10000000 -> 1.2776 | N57: =COUNTIF(Revenue!$D$2:$D$4092,$L57) -> 327 | O57: =SUMIF(Revenue!$D$2:$D$4092,$L57,Revenue!$L$2:$L$4092)/COUNTIF(Revenue!$D$2:$D$4092,$L57) -> 39070.336
B58: =TEXT($G58,"mmm yy") -> Dec 24 | C58: =SUMIF(Revenue!$E$2:$E$4092,$G58,Revenue!$L$2:$L$4092)/100000 -> 105.893 | D58: =SUMIF(Revenue!$E$2:$E$4092,$G58,Revenue!$O$2:$O$4092)/100000 -> 98.3468 | E58: =SUMIF(Revenue!$E$2:$E$4092,$G58,Revenue!$N$2:$N$4092)/100000 -> 7.5462 | F58: =SUMIF(Revenue!$E$2:$E$4092,$G58,Revenue!$G$2:$G$4092) -> 766 | G58: 45627 | I58: Spa | J58: =SUM(Revenue!$J$2:$J$4092)/10000000 -> 0.695981 | L58: Manali | M58: =SUMIF(Revenue!$D$2:$D$4092,$L58,Revenue!$L$2:$L$4092)/10000000 -> 1.417134 | N58: =COUNTIF(Revenue!$D$2:$D$4092,$L58) -> 304 | O58: =SUMIF(Revenue!$D$2:$D$4092,$L58,Revenue!$L$2:$L$4092)/COUNTIF(Revenue!$D$2:$D$4092,$L58) -> 46616.25
B59: =TEXT($G59,"mmm yy") -> Jan 25 | C59: =SUMIF(Revenue!$E$2:$E$4092,$G59,Revenue!$L$2:$L$4092)/100000 -> 122.6831 | D59: =SUMIF(Revenue!$E$2:$E$4092,$G59,Revenue!$O$2:$O$4092)/100000 -> 113.87999 | E59: =SUMIF(Revenue!$E$2:$E$4092,$G59,Revenue!$N$2:$N$4092)/100000 -> 8.803115 | F59: =SUMIF(Revenue!$E$2:$E$4092,$G59,Revenue!$G$2:$G$4092) -> 802 | G59: 45658 | I59: Other | J59: =SUM(Revenue!$K$2:$K$4092)/10000000 -> 0.225322 | L59: Agra | M59: =SUMIF(Revenue!$D$2:$D$4092,$L59,Revenue!$L$2:$L$4092)/10000000 -> 1.538503 | N59: =COUNTIF(Revenue!$D$2:$D$4092,$L59) -> 371 | O59: =SUMIF(Revenue!$D$2:$D$4092,$L59,Revenue!$L$2:$L$4092)/COUNTIF(Revenue!$D$2:$D$4092,$L59) -> 41469.084
B60: =TEXT($G60,"mmm yy") -> Feb 25 | C60: =SUMIF(Revenue!$E$2:$E$4092,$G60,Revenue!$L$2:$L$4092)/100000 -> 130.0396 | D60: =SUMIF(Revenue!$E$2:$E$4092,$G60,Revenue!$O$2:$O$4092)/100000 -> 121.19155 | E60: =SUMIF(Revenue!$E$2:$E$4092,$G60,Revenue!$N$2:$N$4092)/100000 -> 8.848055 | F60: =SUMIF(Revenue!$E$2:$E$4092,$G60,Revenue!$G$2:$G$4092) -> 929 | G60: 45689 | L60: Rishikesh | M60: =SUMIF(Revenue!$D$2:$D$4092,$L60,Revenue!$L$2:$L$4092)/10000000 -> 1.56418 | N60: =COUNTIF(Revenue!$D$2:$D$4092,$L60) -> 363 | O60: =SUMIF(Revenue!$D$2:$D$4092,$L60,Revenue!$L$2:$L$4092)/COUNTIF(Revenue!$D$2:$D$4092,$L60) -> 43090.358
B61: =TEXT($G61,"mmm yy") -> Mar 25 | C61: =SUMIF(Revenue!$E$2:$E$4092,$G61,Revenue!$L$2:$L$4092)/100000 -> 77.3563 | D61: =SUMIF(Revenue!$E$2:$E$4092,$G61,Revenue!$O$2:$O$4092)/100000 -> 72.273365 | E61: =SUMIF(Revenue!$E$2:$E$4092,$G61,Revenue!$N$2:$N$4092)/100000 -> 5.082935 | F61: =SUMIF(Revenue!$E$2:$E$4092,$G61,Revenue!$G$2:$G$4092) -> 593 | G61: 45717 | L61: Bengaluru | M61: =SUMIF(Revenue!$D$2:$D$4092,$L61,Revenue!$L$2:$L$4092)/10000000 -> 1.789945 | N61: =COUNTIF(Revenue!$D$2:$D$4092,$L61) -> 313 | O61: =SUMIF(Revenue!$D$2:$D$4092,$L61,Revenue!$L$2:$L$4092)/COUNTIF(Revenue!$D$2:$D$4092,$L61) -> 57186.741
B62: =TEXT($G62,"mmm yy") -> Apr 25 | C62: =SUMIF(Revenue!$E$2:$E$4092,$G62,Revenue!$L$2:$L$4092)/100000 -> 62.5535 | D62: =SUMIF(Revenue!$E$2:$E$4092,$G62,Revenue!$O$2:$O$4092)/100000 -> 57.962025 | E62: =SUMIF(Revenue!$E$2:$E$4092,$G62,Revenue!$N$2:$N$4092)/100000 -> 4.591475 | F62: =SUMIF(Revenue!$E$2:$E$4092,$G62,Revenue!$G$2:$G$4092) -> 504 | G62: 45748 | L62: Jaipur | M62: =SUMIF(Revenue!$D$2:$D$4092,$L62,Revenue!$L$2:$L$4092)/10000000 -> 1.828537 | N62: =COUNTIF(Revenue!$D$2:$D$4092,$L62) -> 373 | O62: =SUMIF(Revenue!$D$2:$D$4092,$L62,Revenue!$L$2:$L$4092)/COUNTIF(Revenue!$D$2:$D$4092,$L62) -> 49022.44
B63: =TEXT($G63,"mmm yy") -> May 25 | C63: =SUMIF(Revenue!$E$2:$E$4092,$G63,Revenue!$L$2:$L$4092)/100000 -> 87.4262 | D63: =SUMIF(Revenue!$E$2:$E$4092,$G63,Revenue!$O$2:$O$4092)/100000 -> 81.645415 | E63: =SUMIF(Revenue!$E$2:$E$4092,$G63,Revenue!$N$2:$N$4092)/100000 -> 5.780785 | F63: =SUMIF(Revenue!$E$2:$E$4092,$G63,Revenue!$G$2:$G$4092) -> 626 | G63: 45778 | L63: Goa | M63: =SUMIF(Revenue!$D$2:$D$4092,$L63,Revenue!$L$2:$L$4092)/10000000 -> 1.9095 | N63: =COUNTIF(Revenue!$D$2:$D$4092,$L63) -> 346 | O63: =SUMIF(Revenue!$D$2:$D$4092,$L63,Revenue!$L$2:$L$4092)/COUNTIF(Revenue!$D$2:$D$4092,$L63) -> 55187.861
B64: =TEXT($G64,"mmm yy") -> Jun 25 | C64: =SUMIF(Revenue!$E$2:$E$4092,$G64,Revenue!$L$2:$L$4092)/100000 -> 48.1573 | D64: =SUMIF(Revenue!$E$2:$E$4092,$G64,Revenue!$O$2:$O$4092)/100000 -> 45.557605 | E64: =SUMIF(Revenue!$E$2:$E$4092,$G64,Revenue!$N$2:$N$4092)/100000 -> 2.599695 | F64: =SUMIF(Revenue!$E$2:$E$4092,$G64,Revenue!$G$2:$G$4092) -> 438 | G64: 45809 | L64: Udaipur | M64: =SUMIF(Revenue!$D$2:$D$4092,$L64,Revenue!$L$2:$L$4092)/10000000 -> 1.928092 | N64: =COUNTIF(Revenue!$D$2:$D$4092,$L64) -> 325 | O64: =SUMIF(Revenue!$D$2:$D$4092,$L64,Revenue!$L$2:$L$4092)/COUNTIF(Revenue!$D$2:$D$4092,$L64) -> 59325.908
B65: =TEXT($G65,"mmm yy") -> Jul 25 | C65: =SUMIF(Revenue!$E$2:$E$4092,$G65,Revenue!$L$2:$L$4092)/100000 -> 52.0091 | D65: =SUMIF(Revenue!$E$2:$E$4092,$G65,Revenue!$O$2:$O$4092)/100000 -> 48.267245 | E65: =SUMIF(Revenue!$E$2:$E$4092,$G65,Revenue!$N$2:$N$4092)/100000 -> 3.741855 | F65: =SUMIF(Revenue!$E$2:$E$4092,$G65,Revenue!$G$2:$G$4092) -> 455 | G65: 45839 | L65: Mumbai | M65: =SUMIF(Revenue!$D$2:$D$4092,$L65,Revenue!$L$2:$L$4092)/10000000 -> 1.973138 | N65: =COUNTIF(Revenue!$D$2:$D$4092,$L65) -> 273 | O65: =SUMIF(Revenue!$D$2:$D$4092,$L65,Revenue!$L$2:$L$4092)/COUNTIF(Revenue!$D$2:$D$4092,$L65) -> 72276.117
B66: =TEXT($G66,"mmm yy") -> Aug 25 | C66: =SUMIF(Revenue!$E$2:$E$4092,$G66,Revenue!$L$2:$L$4092)/100000 -> 33.113 | D66: =SUMIF(Revenue!$E$2:$E$4092,$G66,Revenue!$O$2:$O$4092)/100000 -> 31.199655 | E66: =SUMIF(Revenue!$E$2:$E$4092,$G66,Revenue!$N$2:$N$4092)/100000 -> 1.913345 | F66: =SUMIF(Revenue!$E$2:$E$4092,$G66,Revenue!$G$2:$G$4092) -> 324 | G66: 45870 | L66: Kochi | M66: =SUMIF(Revenue!$D$2:$D$4092,$L66,Revenue!$L$2:$L$4092)/10000000 -> 2.067608 | N66: =COUNTIF(Revenue!$D$2:$D$4092,$L66) -> 417 | O66: =SUMIF(Revenue!$D$2:$D$4092,$L66,Revenue!$L$2:$L$4092)/COUNTIF(Revenue!$D$2:$D$4092,$L66) -> 49582.926
B67: =TEXT($G67,"mmm yy") -> Sep 25 | C67: =SUMIF(Revenue!$E$2:$E$4092,$G67,Revenue!$L$2:$L$4092)/100000 -> 55.1641 | D67: =SUMIF(Revenue!$E$2:$E$4092,$G67,Revenue!$O$2:$O$4092)/100000 -> 51.93477 | E67: =SUMIF(Revenue!$E$2:$E$4092,$G67,Revenue!$N$2:$N$4092)/100000 -> 3.22933 | F67: =SUMIF(Revenue!$E$2:$E$4092,$G67,Revenue!$G$2:$G$4092) -> 534 | G67: 45901 | L67: New Delhi | M67: =SUMIF(Revenue!$D$2:$D$4092,$L67,Revenue!$L$2:$L$4092)/10000000 -> 2.446627 | N67: =COUNTIF(Revenue!$D$2:$D$4092,$L67) -> 387 | O67: =SUMIF(Revenue!$D$2:$D$4092,$L67,Revenue!$L$2:$L$4092)/COUNTIF(Revenue!$D$2:$D$4092,$L67) -> 63220.336
B68: =TEXT($G68,"mmm yy") -> Oct 25 | C68: =SUMIF(Revenue!$E$2:$E$4092,$G68,Revenue!$L$2:$L$4092)/100000 -> 114.8843 | D68: =SUMIF(Revenue!$E$2:$E$4092,$G68,Revenue!$O$2:$O$4092)/100000 -> 106.40882 | E68: =SUMIF(Revenue!$E$2:$E$4092,$G68,Revenue!$N$2:$N$4092)/100000 -> 8.47548 | F68: =SUMIF(Revenue!$E$2:$E$4092,$G68,Revenue!$G$2:$G$4092) -> 828 | G68: 45931
B69: =TEXT($G69,"mmm yy") -> Nov 25 | C69: =SUMIF(Revenue!$E$2:$E$4092,$G69,Revenue!$L$2:$L$4092)/100000 -> 117.3513 | D69: =SUMIF(Revenue!$E$2:$E$4092,$G69,Revenue!$O$2:$O$4092)/100000 -> 110.20204 | E69: =SUMIF(Revenue!$E$2:$E$4092,$G69,Revenue!$N$2:$N$4092)/100000 -> 7.14926 | F69: =SUMIF(Revenue!$E$2:$E$4092,$G69,Revenue!$G$2:$G$4092) -> 799 | G69: 45962
B70: =TEXT($G70,"mmm yy") -> Dec 25 | C70: =SUMIF(Revenue!$E$2:$E$4092,$G70,Revenue!$L$2:$L$4092)/100000 -> 139.3968 | D70: =SUMIF(Revenue!$E$2:$E$4092,$G70,Revenue!$O$2:$O$4092)/100000 -> 129.1721 | E70: =SUMIF(Revenue!$E$2:$E$4092,$G70,Revenue!$N$2:$N$4092)/100000 -> 10.224695 | F70: =SUMIF(Revenue!$E$2:$E$4092,$G70,Revenue!$G$2:$G$4092) -> 1037 | G70: 45992
B71: =TEXT($G71,"mmm yy") -> Jan 26 | C71: =SUMIF(Revenue!$E$2:$E$4092,$G71,Revenue!$L$2:$L$4092)/100000 -> 137.7538 | D71: =SUMIF(Revenue!$E$2:$E$4092,$G71,Revenue!$O$2:$O$4092)/100000 -> 127.28205 | E71: =SUMIF(Revenue!$E$2:$E$4092,$G71,Revenue!$N$2:$N$4092)/100000 -> 10.471745 | F71: =SUMIF(Revenue!$E$2:$E$4092,$G71,Revenue!$G$2:$G$4092) -> 978 | G71: 46023
B72: =TEXT($G72,"mmm yy") -> Feb 26 | C72: =SUMIF(Revenue!$E$2:$E$4092,$G72,Revenue!$L$2:$L$4092)/100000 -> 125.5117 | D72: =SUMIF(Revenue!$E$2:$E$4092,$G72,Revenue!$O$2:$O$4092)/100000 -> 116.34386 | E72: =SUMIF(Revenue!$E$2:$E$4092,$G72,Revenue!$N$2:$N$4092)/100000 -> 9.167845 | F72: =SUMIF(Revenue!$E$2:$E$4092,$G72,Revenue!$G$2:$G$4092) -> 845 | G72: 46054
B73: =TEXT($G73,"mmm yy") -> Mar 26 | C73: =SUMIF(Revenue!$E$2:$E$4092,$G73,Revenue!$L$2:$L$4092)/100000 -> 110.5096 | D73: =SUMIF(Revenue!$E$2:$E$4092,$G73,Revenue!$O$2:$O$4092)/100000 -> 102.52057 | E73: =SUMIF(Revenue!$E$2:$E$4092,$G73,Revenue!$N$2:$N$4092)/100000 -> 7.989025 | F73: =SUMIF(Revenue!$E$2:$E$4092,$G73,Revenue!$G$2:$G$4092) -> 751 | G73: 46082
B74: =TEXT($G74,"mmm yy") -> Apr 26 | C74: =SUMIF(Revenue!$E$2:$E$4092,$G74,Revenue!$L$2:$L$4092)/100000 -> 83.0251 | D74: =SUMIF(Revenue!$E$2:$E$4092,$G74,Revenue!$O$2:$O$4092)/100000 -> 76.755805 | E74: =SUMIF(Revenue!$E$2:$E$4092,$G74,Revenue!$N$2:$N$4092)/100000 -> 6.269295 | F74: =SUMIF(Revenue!$E$2:$E$4092,$G74,Revenue!$G$2:$G$4092) -> 691 | G74: 46113
B75: =TEXT($G75,"mmm yy") -> May 26 | C75: =SUMIF(Revenue!$E$2:$E$4092,$G75,Revenue!$L$2:$L$4092)/100000 -> 95.7539 | D75: =SUMIF(Revenue!$E$2:$E$4092,$G75,Revenue!$O$2:$O$4092)/100000 -> 88.27137 | E75: =SUMIF(Revenue!$E$2:$E$4092,$G75,Revenue!$N$2:$N$4092)/100000 -> 7.48253 | F75: =SUMIF(Revenue!$E$2:$E$4092,$G75,Revenue!$G$2:$G$4092) -> 774 | G75: 46143
B76: =TEXT($G76,"mmm yy") -> Jun 26 | C76: =SUMIF(Revenue!$E$2:$E$4092,$G76,Revenue!$L$2:$L$4092)/100000 -> 58.3623 | D76: =SUMIF(Revenue!$E$2:$E$4092,$G76,Revenue!$O$2:$O$4092)/100000 -> 54.69573 | E76: =SUMIF(Revenue!$E$2:$E$4092,$G76,Revenue!$N$2:$N$4092)/100000 -> 3.66657 | F76: =SUMIF(Revenue!$E$2:$E$4092,$G76,Revenue!$G$2:$G$4092) -> 540 | G76: 46174
B77: =TEXT($G77,"mmm yy") -> Jul 26 | C77: =SUMIF(Revenue!$E$2:$E$4092,$G77,Revenue!$L$2:$L$4092)/100000 -> 36.1165 | D77: =SUMIF(Revenue!$E$2:$E$4092,$G77,Revenue!$O$2:$O$4092)/100000 -> 33.792555 | E77: =SUMIF(Revenue!$E$2:$E$4092,$G77,Revenue!$N$2:$N$4092)/100000 -> 2.323945 | F77: =SUMIF(Revenue!$E$2:$E$4092,$G77,Revenue!$G$2:$G$4092) -> 379 | G77: 46204
B78: =TEXT($G78,"mmm yy") -> Aug 26 | C78: =SUMIF(Revenue!$E$2:$E$4092,$G78,Revenue!$L$2:$L$4092)/100000 -> 51.1104 | D78: =SUMIF(Revenue!$E$2:$E$4092,$G78,Revenue!$O$2:$O$4092)/100000 -> 48.16393 | E78: =SUMIF(Revenue!$E$2:$E$4092,$G78,Revenue!$N$2:$N$4092)/100000 -> 2.94647 | F78: =SUMIF(Revenue!$E$2:$E$4092,$G78,Revenue!$G$2:$G$4092) -> 444 | G78: 46235
B79: =TEXT($G79,"mmm yy") -> Sep 26 | C79: =SUMIF(Revenue!$E$2:$E$4092,$G79,Revenue!$L$2:$L$4092)/100000 -> 52.0238 | D79: =SUMIF(Revenue!$E$2:$E$4092,$G79,Revenue!$O$2:$O$4092)/100000 -> 48.683225 | E79: =SUMIF(Revenue!$E$2:$E$4092,$G79,Revenue!$N$2:$N$4092)/100000 -> 3.340575 | F79: =SUMIF(Revenue!$E$2:$E$4092,$G79,Revenue!$G$2:$G$4092) -> 490 | G79: 46266
B82: By channel
B83: Channel | C83: Gross (Cr) | D83: Commission (Cr) | E83: Commission %
B84: Walk-in | C84: =SUMIF(Revenue!$F$2:$F$4092,$B84,Revenue!$L$2:$L$4092)/10000000 -> 0.611855 | D84: =SUMIF(Revenue!$F$2:$F$4092,$B84,Revenue!$N$2:$N$4092)/10000000 -> 0 | E84: =SUMIF(Revenue!$F$2:$F$4092,$B84,Revenue!$N$2:$N$4092)/SUMIF(Revenue!$F$2:$F$4092,$B84,Revenue!$L$2:$L$4092) -> 0
B85: OTA - Agoda | C85: =SUMIF(Revenue!$F$2:$F$4092,$B85,Revenue!$L$2:$L$4092)/10000000 -> 1.554501 | D85: =SUMIF(Revenue!$F$2:$F$4092,$B85,Revenue!$N$2:$N$4092)/10000000 -> 0.2096392 | E85: =SUMIF(Revenue!$F$2:$F$4092,$B85,Revenue!$N$2:$N$4092)/SUMIF(Revenue!$F$2:$F$4092,$B85,Revenue!$L$2:$L$4092) -> 0.13485948
B86: Corporate Booking | C86: =SUMIF(Revenue!$F$2:$F$4092,$B86,Revenue!$L$2:$L$4092)/10000000 -> 1.712247 | D86: =SUMIF(Revenue!$F$2:$F$4092,$B86,Revenue!$N$2:$N$4092)/10000000 -> 0.074126 | E86: =SUMIF(Revenue!$F$2:$F$4092,$B86,Revenue!$N$2:$N$4092)/SUMIF(Revenue!$F$2:$F$4092,$B86,Revenue!$L$2:$L$4092) -> 0.043291651
B87: OTA - Booking.com | C87: =SUMIF(Revenue!$F$2:$F$4092,$B87,Revenue!$L$2:$L$4092)/10000000 -> 2.467977 | D87: =SUMIF(Revenue!$F$2:$F$4092,$B87,Revenue!$N$2:$N$4092)/10000000 -> 0.3529812 | E87: =SUMIF(Revenue!$F$2:$F$4092,$B87,Revenue!$N$2:$N$4092)/SUMIF(Revenue!$F$2:$F$4092,$B87,Revenue!$L$2:$L$4092) -> 0.14302451
B88: Mobile App | C88: =SUMIF(Revenue!$F$2:$F$4092,$B88,Revenue!$L$2:$L$4092)/10000000 -> 2.870666 | D88: =SUMIF(Revenue!$F$2:$F$4092,$B88,Revenue!$N$2:$N$4092)/10000000 -> 0 | E88: =SUMIF(Revenue!$F$2:$F$4092,$B88,Revenue!$N$2:$N$4092)/SUMIF(Revenue!$F$2:$F$4092,$B88,Revenue!$L$2:$L$4092) -> 0
B89: OTA - MakeMyTrip | C89: =SUMIF(Revenue!$F$2:$F$4092,$B89,Revenue!$L$2:$L$4092)/10000000 -> 3.470034 | D89: =SUMIF(Revenue!$F$2:$F$4092,$B89,Revenue!$N$2:$N$4092)/10000000 -> 0.44229975 | E89: =SUMIF(Revenue!$F$2:$F$4092,$B89,Revenue!$N$2:$N$4092)/SUMIF(Revenue!$F$2:$F$4092,$B89,Revenue!$L$2:$L$4092) -> 0.12746266
B90: Direct Website | C90: =SUMIF(Revenue!$F$2:$F$4092,$B90,Revenue!$L$2:$L$4092)/10000000 -> 3.878794 | D90: =SUMIF(Revenue!$F$2:$F$4092,$B90,Revenue!$N$2:$N$4092)/10000000 -> 0 | E90: =SUMIF(Revenue!$F$2:$F$4092,$B90,Revenue!$N$2:$N$4092)/SUMIF(Revenue!$F$2:$F$4092,$B90,Revenue!$L$2:$L$4092) -> 0
B91: Travel Agent | C91: =SUMIF(Revenue!$F$2:$F$4092,$B91,Revenue!$L$2:$L$4092)/10000000 -> 4.272358 | D91: =SUMIF(Revenue!$F$2:$F$4092,$B91,Revenue!$N$2:$N$4092)/10000000 -> 0.3665655 | E91: =SUMIF(Revenue!$F$2:$F$4092,$B91,Revenue!$N$2:$N$4092)/SUMIF(Revenue!$F$2:$F$4092,$B91,Revenue!$L$2:$L$4092) -> 0.085799341

Sheet Reviews
A1: Review_ID | B1: Booking_ID | C1: Customer_ID | D1: Hotel_ID | E1: Review_Date | F1: Overall_Rating | G1: Cleanliness | H1: Service | I1: Location | J1: Value_For_Money | K1: Likelihood_To_Recommend | L1: Sentiment | M1: NPS_Category | N1: Review_Source
A2: RV00001 | B2: BK00005 | C2: C0702 | D2: H020 | E2: 45573 | F2: 5 | G2: 5 | H2: 4 | I2: 5 | J2: 5 | K2: 8 | L2: =IF(F2>=4,"Positive",IF(F2=3,"Neutral","Negative")) -> Positive | M2: =IF(K2>=9,"Promoter",IF(K2>=7,"Passive","Detractor")) -> Passive | N2: Booking.com
